## GO语言错误处理

---

GO语言没有类似于js的try-cache用于处理错误信息，而是把错误信息当作返回值来接收  
这是一种显式的错误处理方式  

---  
### GO语言内建error接口
GO语言有一个内建的error接口，所有的错误信息都必须实现这个接口
```
type error interface {
    Error() string
}

```
比如我们有一段业务逻辑，它返回了一个错误对象，我们就可以通过错误对象的Error方法来读取这个错误信息  

### 创建错误的方法
创建错误的方法主要有两种：  
- 第一种```err := errors.New("发生错误")```
- 第二种`err := fmt.Errorf("调用失败，原因：%w", errOriginal)`

### 自定义错误类型

一般来说，普通的错误只包含错误信息，错误类型。但是我们可以自定义一个错误类型来包含更多的信息  
```
type MyError struct {
	Code      int    //错误代码
	Message   string //错误信息
	ErrorTime string //错误发生时间，也就是这个结构体被创建的时间
}

// 然后我们使用一个工厂函数来创建对应的实例
func NewMyError(code int, message string) *MyError {
	return &MyError{
		Code:      code,
		Message:   message,
		ErrorTime: time.Now().Format("2006-01-02 15:04:05"),
	}
}

//这里还隐式的实现了内建error接口
func (e *MyError) Error() string {
	return fmt.Sprintf("MyError:Code:%d,Message:%s,time:%s", e.Code, e.Message, e.ErrorTime)
}

// 然后想创建返回错误信息的时候就可以使用以下代码
func main() {
	err := NewMyError(404, "page not found")
	fmt.Println(err.Error())
	time.Sleep(1 * time.Second)
	fmt.Println(err.ErrorTime)
}

```

### 错误链
错误链就是一个错误包装另一个错误
```
func main() {
	baseErr := errors.New("数据库连接失败")
	wrapErr := fmt.Errorf("初始化失败: %w", baseErr)
	fmt.Println(wrapErr.Error())
}
//最后输出初始化失败: 数据库连接失败
```
---
### 错误判断工具
| errors.Is                                     | errors.As                          | errors.Unwrap                   |
|-----------------------------------------------|------------------------------------|---------------------------------|
| errors.Is(err, target)：判断 err 是否是 target 类型/值 | errors.As(err, &target)：断言并转换为某个类型 | errors.Unwrap(err)：获取底层错误（原始错误） |  

---
### panic and recover
有时候有一些错误会影响程序的正常运行，比如数组越界、空指针这些。
这时候就需要用到panic，panic会根据调用链来冒泡结束函数  


比如：假如有调用链 a>b>c>d四个函数，d函数panic了，就会找d的defer，然后依次向上  
直到有recover捕获这个panic，或者一直到所有函数结束都没有recover捕获panic导致程序结束。panic被捕获之后不会影响接下来的程序运行  

```
package main

import "fmt"

func a() {
	defer func() {
		if r := recover(); r != nil {
			fmt.Println("a() 捕获到了 panic:", r)
		}
	}()
	b()
	fmt.Println("a() 正常结束")
}

func b() {
	c()
}

func c() {
	d()
}

func d() {
	panic("d() 出现了致命错误")
}

func main() {
	a()
	fmt.Println("main 函数继续执行")
}

```
最后的结果是虽然出现了panic，但是由于我们捕获了panic，所以程序还是会继续运行  
并且！！！recover只能在defer中调用